<?xml version="1.0" ?>
<sdf version='1.7'>
  <model name='rrbot'>
    <joint name='fixed' type='fixed'>
      <pose relative_to='__model__'>0 0 0 0 -0 0</pose>
      <parent>world</parent>
      <child>BaseLink</child>
    </joint>
    <link name='BaseLink'>
      <pose relative_to='fixed'>0 0 0 0 -0 0</pose>
      <inertial>
        <pose>0 0 1 0 -0 0</pose>
        <mass>1</mass>
        <inertia>
          <ixx>0.334167</ixx>
          <ixy>0</ixy>
          <ixz>0</ixz>
          <iyy>0.334167</iyy>
          <iyz>0</iyz>
          <izz>0.00166667</izz>
        </inertia>
      </inertial>
      <collision name='BaseLink_collision'>
        <pose>0 0 1 0 -0 0</pose>
        <geometry>
          <box>
            <size>0.1 0.1 2</size>
          </box>
        </geometry>
      </collision>
      <visual name='BaseLink_visual'>
        <pose>0 0 1 0 -0 0</pose>
        <geometry>
          <box>
            <size>0.1 0.1 2</size>
          </box>
        </geometry>
      </visual>
      <gravity>1</gravity>
      <velocity_decay/>
      <self_collide>1</self_collide>
    </link>
    <joint name='ArmJoint' type='revolute'>
      <pose relative_to='BaseLink'>0 0.1 1.95 0 0.5 0</pose>
      <parent>BaseLink</parent>
      <child>ArmLink</child>
      <axis>
        <xyz>0 1 0</xyz>
        <limit>
          <lower>-3.14</lower>
          <upper>3.14</upper>
          <effort>320</effort>
          <velocity>4.5</velocity>
        </limit>
      </axis>
    </joint>
    <link name='ArmLink'>
      <pose relative_to='ArmJoint'>0 0 0.45 0 -0 0</pose>
      <inertial>
        <pose>0 0 1.95 0 -0 0</pose>
        <mass>1</mass>
        <inertia>
          <ixx>0.334167</ixx>
          <ixy>0</ixy>
          <ixz>0</ixz>
          <iyy>0.334167</iyy>
          <iyz>0</iyz>
          <izz>0.00166667</izz>
        </inertia>
      </inertial>
      <collision name='ArmLink_collision'>
        <pose>0 0 0 0 -0 0</pose>
        <geometry>
          <box>
            <size>0.1 0.1 1</size>
          </box>
        </geometry>
      </collision>
      <visual name='ArmLink_visual'>
        <pose>0 0 0 0 -0 0</pose>
        <geometry>
          <box>
            <size>0.1 0.1 1</size>
          </box>
        </geometry>
      </visual>
      <gravity>1</gravity>
      <velocity_decay/>
      <self_collide>1</self_collide>
    </link>
    <plugin name="model_push" filename="libtest_bench.so"/>
  </model>
</sdf>
